2023-10-01 18:36:59,386 ERROR: Exception on /index [POST] [in C:\Users\User\Desktop\flask-mega\.venv\lib\site-packages\flask\app.py:1414]
Traceback (most recent call last):
  File "C:\Users\User\Desktop\flask-mega\.venv\lib\site-packages\sqlalchemy\engine\base.py", line 1965, in _exec_single_context
    self.dialect.do_execute(
  File "C:\Users\User\Desktop\flask-mega\.venv\lib\site-packages\sqlalchemy\engine\default.py", line 921, in do_execute
    cursor.execute(statement, parameters)
  File "C:\Users\User\Desktop\flask-mega\.venv\lib\site-packages\pymysql\cursors.py", line 153, in execute
    result = self._query(query)
  File "C:\Users\User\Desktop\flask-mega\.venv\lib\site-packages\pymysql\cursors.py", line 322, in _query
    conn.query(q)
  File "C:\Users\User\Desktop\flask-mega\.venv\lib\site-packages\pymysql\connections.py", line 558, in query
    self._affected_rows = self._read_query_result(unbuffered=unbuffered)
  File "C:\Users\User\Desktop\flask-mega\.venv\lib\site-packages\pymysql\connections.py", line 822, in _read_query_result
    result.read()
  File "C:\Users\User\Desktop\flask-mega\.venv\lib\site-packages\pymysql\connections.py", line 1200, in read
    first_packet = self.connection._read_packet()
  File "C:\Users\User\Desktop\flask-mega\.venv\lib\site-packages\pymysql\connections.py", line 772, in _read_packet
    packet.raise_for_error()
  File "C:\Users\User\Desktop\flask-mega\.venv\lib\site-packages\pymysql\protocol.py", line 221, in raise_for_error
    err.raise_mysql_exception(self._data)
  File "C:\Users\User\Desktop\flask-mega\.venv\lib\site-packages\pymysql\err.py", line 143, in raise_mysql_exception
    raise errorclass(errno, errval)
pymysql.err.DataError: (1406, "Data too long for column 'body' at row 1")

The above exception was the direct cause of the following exception:

Traceback (most recent call last):
  File "C:\Users\User\Desktop\flask-mega\.venv\lib\site-packages\flask\app.py", line 2190, in wsgi_app
    response = self.full_dispatch_request()
  File "C:\Users\User\Desktop\flask-mega\.venv\lib\site-packages\flask\app.py", line 1486, in full_dispatch_request
    rv = self.handle_user_exception(e)
  File "C:\Users\User\Desktop\flask-mega\.venv\lib\site-packages\flask\app.py", line 1484, in full_dispatch_request
    rv = self.dispatch_request()
  File "C:\Users\User\Desktop\flask-mega\.venv\lib\site-packages\flask\app.py", line 1469, in dispatch_request
    return self.ensure_sync(self.view_functions[rule.endpoint])(**view_args)
  File "C:\Users\User\Desktop\flask-mega\.venv\lib\site-packages\flask_login\utils.py", line 290, in decorated_view
    return current_app.ensure_sync(func)(*args, **kwargs)
  File "C:\Users\User\Desktop\flask-mega\app\main\routes.py", line 38, in index
    db.session.commit()
  File "C:\Users\User\Desktop\flask-mega\.venv\lib\site-packages\sqlalchemy\orm\scoping.py", line 554, in commit
    return self._proxied.commit()
  File "C:\Users\User\Desktop\flask-mega\.venv\lib\site-packages\sqlalchemy\orm\session.py", line 1923, in commit
    trans.commit(_to_root=True)
  File "<string>", line 2, in commit
  File "C:\Users\User\Desktop\flask-mega\.venv\lib\site-packages\sqlalchemy\orm\state_changes.py", line 139, in _go
    ret_value = fn(self, *arg, **kw)
  File "C:\Users\User\Desktop\flask-mega\.venv\lib\site-packages\sqlalchemy\orm\session.py", line 1239, in commit
    self._prepare_impl()
  File "<string>", line 2, in _prepare_impl
  File "C:\Users\User\Desktop\flask-mega\.venv\lib\site-packages\sqlalchemy\orm\state_changes.py", line 139, in _go
    ret_value = fn(self, *arg, **kw)
  File "C:\Users\User\Desktop\flask-mega\.venv\lib\site-packages\sqlalchemy\orm\session.py", line 1214, in _prepare_impl
    self.session.flush()
  File "C:\Users\User\Desktop\flask-mega\.venv\lib\site-packages\sqlalchemy\orm\session.py", line 4179, in flush
    self._flush(objects)
  File "C:\Users\User\Desktop\flask-mega\.venv\lib\site-packages\sqlalchemy\orm\session.py", line 4315, in _flush
    transaction.rollback(_capture_exception=True)
  File "C:\Users\User\Desktop\flask-mega\.venv\lib\site-packages\sqlalchemy\util\langhelpers.py", line 147, in __exit__
    raise exc_value.with_traceback(exc_tb)
  File "C:\Users\User\Desktop\flask-mega\.venv\lib\site-packages\sqlalchemy\orm\session.py", line 4275, in _flush
    flush_context.execute()
  File "C:\Users\User\Desktop\flask-mega\.venv\lib\site-packages\sqlalchemy\orm\unitofwork.py", line 466, in execute
    rec.execute(self)
  File "C:\Users\User\Desktop\flask-mega\.venv\lib\site-packages\sqlalchemy\orm\unitofwork.py", line 642, in execute
    util.preloaded.orm_persistence.save_obj(
  File "C:\Users\User\Desktop\flask-mega\.venv\lib\site-packages\sqlalchemy\orm\persistence.py", line 93, in save_obj
    _emit_insert_statements(
  File "C:\Users\User\Desktop\flask-mega\.venv\lib\site-packages\sqlalchemy\orm\persistence.py", line 1226, in _emit_insert_statements
    result = connection.execute(
  File "C:\Users\User\Desktop\flask-mega\.venv\lib\site-packages\sqlalchemy\engine\base.py", line 1412, in execute
    return meth(
  File "C:\Users\User\Desktop\flask-mega\.venv\lib\site-packages\sqlalchemy\sql\elements.py", line 515, in _execute_on_connection
    return connection._execute_clauseelement(
  File "C:\Users\User\Desktop\flask-mega\.venv\lib\site-packages\sqlalchemy\engine\base.py", line 1635, in _execute_clauseelement
    ret = self._execute_context(
  File "C:\Users\User\Desktop\flask-mega\.venv\lib\site-packages\sqlalchemy\engine\base.py", line 1844, in _execute_context
    return self._exec_single_context(
  File "C:\Users\User\Desktop\flask-mega\.venv\lib\site-packages\sqlalchemy\engine\base.py", line 1984, in _exec_single_context
    self._handle_dbapi_exception(
  File "C:\Users\User\Desktop\flask-mega\.venv\lib\site-packages\sqlalchemy\engine\base.py", line 2339, in _handle_dbapi_exception
    raise sqlalchemy_exception.with_traceback(exc_info[2]) from e
  File "C:\Users\User\Desktop\flask-mega\.venv\lib\site-packages\sqlalchemy\engine\base.py", line 1965, in _exec_single_context
    self.dialect.do_execute(
  File "C:\Users\User\Desktop\flask-mega\.venv\lib\site-packages\sqlalchemy\engine\default.py", line 921, in do_execute
    cursor.execute(statement, parameters)
  File "C:\Users\User\Desktop\flask-mega\.venv\lib\site-packages\pymysql\cursors.py", line 153, in execute
    result = self._query(query)
  File "C:\Users\User\Desktop\flask-mega\.venv\lib\site-packages\pymysql\cursors.py", line 322, in _query
    conn.query(q)
  File "C:\Users\User\Desktop\flask-mega\.venv\lib\site-packages\pymysql\connections.py", line 558, in query
    self._affected_rows = self._read_query_result(unbuffered=unbuffered)
  File "C:\Users\User\Desktop\flask-mega\.venv\lib\site-packages\pymysql\connections.py", line 822, in _read_query_result
    result.read()
  File "C:\Users\User\Desktop\flask-mega\.venv\lib\site-packages\pymysql\connections.py", line 1200, in read
    first_packet = self.connection._read_packet()
  File "C:\Users\User\Desktop\flask-mega\.venv\lib\site-packages\pymysql\connections.py", line 772, in _read_packet
    packet.raise_for_error()
  File "C:\Users\User\Desktop\flask-mega\.venv\lib\site-packages\pymysql\protocol.py", line 221, in raise_for_error
    err.raise_mysql_exception(self._data)
  File "C:\Users\User\Desktop\flask-mega\.venv\lib\site-packages\pymysql\err.py", line 143, in raise_mysql_exception
    raise errorclass(errno, errval)
sqlalchemy.exc.DataError: (pymysql.err.DataError) (1406, "Data too long for column 'body' at row 1")
[SQL: INSERT INTO post (body, timestamp, user_id, language) VALUES (%(body)s, %(timestamp)s, %(user_id)s, %(language)s)]
[parameters: {'body': "return render_template('errors/500.html'), 500 \r\ngodo said 3 minutes ago\r\nlorem ipsum dolor lorem ipsum dolor lorem ipsum dolor lorem ipsum dolor ... (4 characters truncated) ... Error: the translation service is not configured.\r\ndo said 11 minutes ago\r\nlorem ipsum dolor\r\nError: the translation service is not configured.", 'timestamp': datetime.datetime(2023, 10, 1, 10, 36, 59, 386493), 'user_id': 1, 'language': 'en'}]
(Background on this error at: https://sqlalche.me/e/20/9h9h)
