2023-10-06 21:14:11,355 ERROR: Exception on /export_posts [GET] [in C:\Users\User\Desktop\flask-mega\.venv\lib\site-packages\flask\app.py:1414]
Traceback (most recent call last):
  File "C:\Users\User\Desktop\flask-mega\.venv\lib\site-packages\flask\app.py", line 2190, in wsgi_app
    response = self.full_dispatch_request()
  File "C:\Users\User\Desktop\flask-mega\.venv\lib\site-packages\flask\app.py", line 1486, in full_dispatch_request
    rv = self.handle_user_exception(e)
  File "C:\Users\User\Desktop\flask-mega\.venv\lib\site-packages\flask\app.py", line 1484, in full_dispatch_request
    rv = self.dispatch_request()
  File "C:\Users\User\Desktop\flask-mega\.venv\lib\site-packages\flask\app.py", line 1469, in dispatch_request
    return self.ensure_sync(self.view_functions[rule.endpoint])(**view_args)
  File "C:\Users\User\Desktop\flask-mega\.venv\lib\site-packages\flask_login\utils.py", line 290, in decorated_view
    return current_app.ensure_sync(func)(*args, **kwargs)
  File "C:\Users\User\Desktop\flask-mega\app\main\routes.py", line 231, in export_posts
    current_user.launch_task('export_posts', _('Exporting posts...'))
  File "C:\Users\User\Desktop\flask-mega\app\models.py", line 161, in launch_task
    db.session.add(task)
  File "C:\Users\User\Desktop\flask-mega\.venv\lib\site-packages\sqlalchemy\orm\scoping.py", line 377, in add
    return self._proxied.add(instance, _warn=_warn)
  File "C:\Users\User\Desktop\flask-mega\.venv\lib\site-packages\sqlalchemy\orm\session.py", line 3355, in add
    self._save_or_update_state(state)
  File "C:\Users\User\Desktop\flask-mega\.venv\lib\site-packages\sqlalchemy\orm\session.py", line 3385, in _save_or_update_state
    self._save_or_update_impl(st_)
  File "C:\Users\User\Desktop\flask-mega\.venv\lib\site-packages\sqlalchemy\orm\session.py", line 4029, in _save_or_update_impl
    self._update_impl(state)
  File "C:\Users\User\Desktop\flask-mega\.venv\lib\site-packages\sqlalchemy\orm\session.py", line 4012, in _update_impl
    to_attach = self._before_attach(state, obj)
  File "C:\Users\User\Desktop\flask-mega\.venv\lib\site-packages\sqlalchemy\orm\session.py", line 4103, in _before_attach
    raise sa_exc.InvalidRequestError(
sqlalchemy.exc.InvalidRequestError: Object '<User at 0x2b2eeafaf70>' is already attached to session '2' (this is '3')
2023-10-06 21:17:58,196 INFO: Microblog startup [in C:\Users\User\Desktop\flask-mega\app\__init__.py:83]
2023-10-06 21:18:07,140 INFO: Microblog startup [in C:\Users\User\Desktop\flask-mega\app\__init__.py:83]
2023-10-06 21:18:07,140 INFO: Microblog startup [in C:\Users\User\Desktop\flask-mega\app\__init__.py:83]
2023-10-06 21:18:07,149 ERROR: Exception on /export_posts [GET] [in C:\Users\User\Desktop\flask-mega\.venv\lib\site-packages\flask\app.py:1414]
Traceback (most recent call last):
  File "C:\Users\User\Desktop\flask-mega\.venv\lib\site-packages\flask\app.py", line 2190, in wsgi_app
    response = self.full_dispatch_request()
  File "C:\Users\User\Desktop\flask-mega\.venv\lib\site-packages\flask\app.py", line 1486, in full_dispatch_request
    rv = self.handle_user_exception(e)
  File "C:\Users\User\Desktop\flask-mega\.venv\lib\site-packages\flask\app.py", line 1484, in full_dispatch_request
    rv = self.dispatch_request()
  File "C:\Users\User\Desktop\flask-mega\.venv\lib\site-packages\flask\app.py", line 1469, in dispatch_request
    return self.ensure_sync(self.view_functions[rule.endpoint])(**view_args)
  File "C:\Users\User\Desktop\flask-mega\.venv\lib\site-packages\flask_login\utils.py", line 290, in decorated_view
    return current_app.ensure_sync(func)(*args, **kwargs)
  File "C:\Users\User\Desktop\flask-mega\app\main\routes.py", line 231, in export_posts
    current_user.launch_task('export_posts', _('Exporting posts...'))
  File "C:\Users\User\Desktop\flask-mega\app\models.py", line 161, in launch_task
    db.session.add(task)
  File "C:\Users\User\Desktop\flask-mega\.venv\lib\site-packages\sqlalchemy\orm\scoping.py", line 377, in add
    return self._proxied.add(instance, _warn=_warn)
  File "C:\Users\User\Desktop\flask-mega\.venv\lib\site-packages\sqlalchemy\orm\session.py", line 3355, in add
    self._save_or_update_state(state)
  File "C:\Users\User\Desktop\flask-mega\.venv\lib\site-packages\sqlalchemy\orm\session.py", line 3385, in _save_or_update_state
    self._save_or_update_impl(st_)
  File "C:\Users\User\Desktop\flask-mega\.venv\lib\site-packages\sqlalchemy\orm\session.py", line 4029, in _save_or_update_impl
    self._update_impl(state)
  File "C:\Users\User\Desktop\flask-mega\.venv\lib\site-packages\sqlalchemy\orm\session.py", line 4012, in _update_impl
    to_attach = self._before_attach(state, obj)
  File "C:\Users\User\Desktop\flask-mega\.venv\lib\site-packages\sqlalchemy\orm\session.py", line 4103, in _before_attach
    raise sa_exc.InvalidRequestError(
sqlalchemy.exc.InvalidRequestError: Object '<User at 0x290ad28ca30>' is already attached to session '2' (this is '3')
2023-10-06 21:18:07,149 ERROR: Exception on /export_posts [GET] [in C:\Users\User\Desktop\flask-mega\.venv\lib\site-packages\flask\app.py:1414]
Traceback (most recent call last):
  File "C:\Users\User\Desktop\flask-mega\.venv\lib\site-packages\flask\app.py", line 2190, in wsgi_app
    response = self.full_dispatch_request()
  File "C:\Users\User\Desktop\flask-mega\.venv\lib\site-packages\flask\app.py", line 1486, in full_dispatch_request
    rv = self.handle_user_exception(e)
  File "C:\Users\User\Desktop\flask-mega\.venv\lib\site-packages\flask\app.py", line 1484, in full_dispatch_request
    rv = self.dispatch_request()
  File "C:\Users\User\Desktop\flask-mega\.venv\lib\site-packages\flask\app.py", line 1469, in dispatch_request
    return self.ensure_sync(self.view_functions[rule.endpoint])(**view_args)
  File "C:\Users\User\Desktop\flask-mega\.venv\lib\site-packages\flask_login\utils.py", line 290, in decorated_view
    return current_app.ensure_sync(func)(*args, **kwargs)
  File "C:\Users\User\Desktop\flask-mega\app\main\routes.py", line 231, in export_posts
    current_user.launch_task('export_posts', _('Exporting posts...'))
  File "C:\Users\User\Desktop\flask-mega\app\models.py", line 161, in launch_task
    db.session.add(task)
  File "C:\Users\User\Desktop\flask-mega\.venv\lib\site-packages\sqlalchemy\orm\scoping.py", line 377, in add
    return self._proxied.add(instance, _warn=_warn)
  File "C:\Users\User\Desktop\flask-mega\.venv\lib\site-packages\sqlalchemy\orm\session.py", line 3355, in add
    self._save_or_update_state(state)
  File "C:\Users\User\Desktop\flask-mega\.venv\lib\site-packages\sqlalchemy\orm\session.py", line 3385, in _save_or_update_state
    self._save_or_update_impl(st_)
  File "C:\Users\User\Desktop\flask-mega\.venv\lib\site-packages\sqlalchemy\orm\session.py", line 4029, in _save_or_update_impl
    self._update_impl(state)
  File "C:\Users\User\Desktop\flask-mega\.venv\lib\site-packages\sqlalchemy\orm\session.py", line 4012, in _update_impl
    to_attach = self._before_attach(state, obj)
  File "C:\Users\User\Desktop\flask-mega\.venv\lib\site-packages\sqlalchemy\orm\session.py", line 4103, in _before_attach
    raise sa_exc.InvalidRequestError(
sqlalchemy.exc.InvalidRequestError: Object '<User at 0x290ad28ca30>' is already attached to session '2' (this is '3')
2023-10-06 21:19:59,797 INFO: Microblog startup [in C:\Users\User\Desktop\flask-mega\app\__init__.py:83]
2023-10-06 21:20:01,933 INFO: Microblog startup [in C:\Users\User\Desktop\flask-mega\app\__init__.py:83]
2023-10-06 21:20:01,933 INFO: Microblog startup [in C:\Users\User\Desktop\flask-mega\app\__init__.py:83]
2023-10-06 21:20:01,940 ERROR: Exception on /export_posts [GET] [in C:\Users\User\Desktop\flask-mega\.venv\lib\site-packages\flask\app.py:1414]
Traceback (most recent call last):
  File "C:\Users\User\Desktop\flask-mega\.venv\lib\site-packages\flask\app.py", line 2190, in wsgi_app
    response = self.full_dispatch_request()
  File "C:\Users\User\Desktop\flask-mega\.venv\lib\site-packages\flask\app.py", line 1486, in full_dispatch_request
    rv = self.handle_user_exception(e)
  File "C:\Users\User\Desktop\flask-mega\.venv\lib\site-packages\flask\app.py", line 1484, in full_dispatch_request
    rv = self.dispatch_request()
  File "C:\Users\User\Desktop\flask-mega\.venv\lib\site-packages\flask\app.py", line 1469, in dispatch_request
    return self.ensure_sync(self.view_functions[rule.endpoint])(**view_args)
  File "C:\Users\User\Desktop\flask-mega\.venv\lib\site-packages\flask_login\utils.py", line 290, in decorated_view
    return current_app.ensure_sync(func)(*args, **kwargs)
  File "C:\Users\User\Desktop\flask-mega\app\main\routes.py", line 231, in export_posts
    current_user.launch_task('export_posts', _('Exporting posts...'))
  File "C:\Users\User\Desktop\flask-mega\app\models.py", line 161, in launch_task
    db.session.add(task)
  File "C:\Users\User\Desktop\flask-mega\.venv\lib\site-packages\sqlalchemy\orm\scoping.py", line 377, in add
    return self._proxied.add(instance, _warn=_warn)
  File "C:\Users\User\Desktop\flask-mega\.venv\lib\site-packages\sqlalchemy\orm\session.py", line 3355, in add
    self._save_or_update_state(state)
  File "C:\Users\User\Desktop\flask-mega\.venv\lib\site-packages\sqlalchemy\orm\session.py", line 3385, in _save_or_update_state
    self._save_or_update_impl(st_)
  File "C:\Users\User\Desktop\flask-mega\.venv\lib\site-packages\sqlalchemy\orm\session.py", line 4029, in _save_or_update_impl
    self._update_impl(state)
  File "C:\Users\User\Desktop\flask-mega\.venv\lib\site-packages\sqlalchemy\orm\session.py", line 4012, in _update_impl
    to_attach = self._before_attach(state, obj)
  File "C:\Users\User\Desktop\flask-mega\.venv\lib\site-packages\sqlalchemy\orm\session.py", line 4103, in _before_attach
    raise sa_exc.InvalidRequestError(
sqlalchemy.exc.InvalidRequestError: Object '<User at 0x147426fc9d0>' is already attached to session '1' (this is '2')
2023-10-06 21:39:16,213 INFO: Microblog startup [in C:\Users\User\Desktop\flask-mega\app\__init__.py:83]
